Workbook

Sheet SQL_Data_Import
A1: reporter_iso3 | B1: reporter_name | C1: reference_year | D1: total_exports_usd | E1: gdp_current_usd | F1: population_total | G1: gdp_growth_annual_pct | H1: trade_pct_of_gdp | I1: export_per_capita | J1: gdp_per_capita | K1: export_to_gdp_ratio_pct | L1: global_export_rank | M1: previous_year_exports | N1: yoy_export_growth_pct | O1: lookup_key
A2: ABW | B2: Aruba | C2: 2015 | D2: 159764410 | E2: 2962906704 | F2: 107906 | G2: 3.6114791 | H2: 140.493 | I2: 1480.59 | J2: 27458.22 | K2: 5.39 | L2: 157 | O2: =vw_scenario_analysis_dataset[[#This Row],[reporter_name]] & "-" & vw_scenario_analysis_dataset[[#This Row],[reference_year]] -> Aruba-2015
A3: ABW | B3: Aruba | C3: 2016 | D3: 1.9079298e+08 | E3: 2983637430 | F3: 108727 | G3: 1.2343354 | H3: 136.88726 | I3: 1754.79 | J3: 27441.55 | K3: 6.39 | L3: 157 | M3: 159764410 | N3: 19.42 | O3: =vw_scenario_analysis_dataset[[#This Row],[reporter_name]] & "-" & vw_scenario_analysis_dataset[[#This Row],[reference_year]] -> Aruba-2016
A4: ABW | B4: Aruba | C4: 2017 | D4: 1.7766667e+08 | E4: 3092427933 | F4: 108735 | G4: 3.4934299 | H4: 138.71662 | I4: 1633.94 | J4: 28440.04 | K4: 5.75 | L4: 159 | M4: 1.9079298e+08 | N4: -6.88 | O4: =vw_scenario_analysis_dataset[[#This Row],[reporter_name]] & "-" & vw_scenario_analysis_dataset[[#This Row],[reference_year]] -> Aruba-2017
A5: ABW | B5: Aruba | C5: 2018 | D5: 1.3894075e+08 | E5: 3276187709 | F5: 108908 | G5: 3.2124711 | H5: 138.82497 | I5: 1275.76 | J5: 30082.16 | K5: 4.24 | L5: 156 | M5: 1.7766667e+08 | N5: -21.8 | O5: =vw_scenario_analysis_dataset[[#This Row],[reporter_name]] & "-" & vw_scenario_analysis_dataset[[#This Row],[reference_year]] -> Aruba-2018
A6: ABW | B6: Aruba | C6: 2019 | D6: 1.5728588e+08 | E6: 3347561739 | F6: 109203 | G6: 1.2291441 | H6: 137.92325 | I6: 1440.31 | J6: 30654.49 | K6: 4.7 | L6: 154 | M6: 1.3894075e+08 | N6: 13.2 | O6: =vw_scenario_analysis_dataset[[#This Row],[reporter_name]] & "-" & vw_scenario_analysis_dataset[[#This Row],[reference_year]] -> Aruba-2019
A7: ABW | B7: Aruba | C7: 2020 | D7: 1.3185945e+08 | E7: 2461056053 | F7: 108587 | G7: -23.940059 | H7: 123.2405 | I7: 1214.32 | J7: 22664.37 | K7: 5.36 | L7: 149 | M7: 1.5728588e+08 | N7: -16.17 | O7: =vw_scenario_analysis_dataset[[#This Row],[reporter_name]] & "-" & vw_scenario_analysis_dataset[[#This Row],[reference_year]] -> Aruba-2020
A8: ABW | B8: Aruba | C8: 2021 | D8: 1.7669402e+08 | E8: 2889305034 | F8: 107700 | G8: 14.833692 | H8: 139.5109 | I8: 1640.61 | J8: 26827.34 | K8: 6.12 | L8: 149 | M8: 1.3185945e+08 | N8: 34 | O8: =vw_scenario_analysis_dataset[[#This Row],[reporter_name]] & "-" & vw_scenario_analysis_dataset[[#This Row],[reference_year]] -> Aruba-2021
A9: ABW | B9: Aruba | C9: 2022 | D9: 2.0959357e+08 | E9: 3326671315 | F9: 107310 | G9: 10.607961 | H9: 160.55814 | I9: 1953.16 | J9: 31000.57 | K9: 6.3 | L9: 148 | M9: 1.7669402e+08 | N9: 18.62 | O9: =vw_scenario_analysis_dataset[[#This Row],[reporter_name]] & "-" & vw_scenario_analysis_dataset[[#This Row],[reference_year]] -> Aruba-2022
A10: ABW | B10: Aruba | C10: 2023 | D10: 2.2200983e+08 | E10: 3746573413 | F10: 107359 | G10: 9.5163602 | H10: 153.71916 | I10: 2067.92 | J10: 34897.62 | K10: 5.93 | L10: 146 | M10: 2.0959357e+08 | N10: 5.92 | O10: =vw_scenario_analysis_dataset[[#This Row],[reporter_name]] & "-" & vw_scenario_analysis_dataset[[#This Row],[reference_year]] -> Aruba-2023
A11: AFG | B11: Afghanistan | C11: 2015 | D11: 1142809936 | E11: 19134221645 | F11: 33831764 | G11: 1.4513147 | I11: 33.78 | J11: 565.57 | K11: 5.97 | L11: 139 | O11: =vw_scenario_analysis_dataset[[#This Row],[reporter_name]] & "-" & vw_scenario_analysis_dataset[[#This Row],[reference_year]] -> Afghanistan-2015
A12: AFG | B12: Afghanistan | C12: 2016 | D12: 1192910671 | E12: 18116572395 | F12: 34700612 | G12: 2.2603142 | I12: 34.38 | J12: 522.08 | K12: 6.58 | L12: 140 | M12: 1142809936 | N12: 4.38 | O12: =vw_scenario_analysis_dataset[[#This Row],[reporter_name]] & "-" & vw_scenario_analysis_dataset[[#This Row],[reference_year]] -> Afghanistan-2016
A13: AFG | B13: Afghanistan | C13: 2017 | D13: 1.6638535e+09 | E13: 18753456498 | F13: 35688935 | G13: 2.6470032 | I13: 46.62 | J13: 525.47 | K13: 8.87 | L13: 138 | M13: 1192910671 | N13: 39.48 | O13: =vw_scenario_analysis_dataset[[#This Row],[reporter_name]] & "-" & vw_scenario_analysis_dataset[[#This Row],[reference_year]] -> Afghanistan-2017
A14: AFG | B14: Afghanistan | C14: 2018 | D14: 1.769009e+09 | E14: 18053222687 | F14: 36743039 | G14: 1.1892281 | I14: 48.15 | J14: 491.34 | K14: 9.8 | L14: 135 | M14: 1.6638535e+09 | N14: 6.32 | O14: =vw_scenario_analysis_dataset[[#This Row],[reporter_name]] & "-" & vw_scenario_analysis_dataset[[#This Row],[reference_year]] -> Afghanistan-2018
A15: AFG | B15: Afghanistan | C15: 2019 | D15: 1.740977e+09 | E15: 18799444490 | F15: 37856121 | G15: 3.9116034 | I15: 45.99 | J15: 496.6 | K15: 9.26 | L15: 136 | M15: 1.769009e+09 | N15: -1.58 | O15: =vw_scenario_analysis_dataset[[#This Row],[reporter_name]] & "-" & vw_scenario_analysis_dataset[[#This Row],[reference_year]] -> Afghanistan-2019
A16: AGO | B16: Angola | C16: 2015 | D16: 6.7849875e+10 | E16: 103000000000 | F16: 28157798 | G16: 0.76317771 | H16: 54.979381 | I16: 2409.63 | J16: 3657.96 | K16: 65.87 | L16: 54 | O16: =vw_scenario_analysis_dataset[[#This Row],[reporter_name]] & "-" & vw_scenario_analysis_dataset[[#This Row],[reference_year]] -> Angola-2015
A17: AGO | B17: Angola | C17: 2016 | D17: 5.6114999e+10 | E17: 60770049747 | F17: 29183070 | G17: -0.23307696 | H17: 46.325613 | I17: 1922.86 | J17: 2082.37 | K17: 92.34 | L17: 55 | M17: 6.7849875e+10 | N17: -17.3 | O17: =vw_scenario_analysis_dataset[[#This Row],[reporter_name]] & "-" & vw_scenario_analysis_dataset[[#This Row],[reference_year]] -> Angola-2016
A18: AGO | B18: Angola | C18: 2017 | D18: 8.3365333e+10 | E18: 85629598654 | F18: 30234839 | G18: -0.16468866 | H18: 44.996325 | I18: 2757.26 | J18: 2832.15 | K18: 97.36 | L18: 49 | M18: 5.6114999e+10 | N18: 48.56 | O18: =vw_scenario_analysis_dataset[[#This Row],[reporter_name]] & "-" & vw_scenario_analysis_dataset[[#This Row],[reference_year]] -> Angola-2017
A19: AGO | B19: Angola | C19: 2018 | D19: 8.1329438e+10 | E19: 90506061877 | F19: 31297155 | G19: -0.50669754 | H19: 58.269895 | I19: 2598.62 | J19: 2891.83 | K19: 89.86 | L19: 51 | M19: 8.3365333e+10 | N19: -2.44 | O19: =vw_scenario_analysis_dataset[[#This Row],[reporter_name]] & "-" & vw_scenario_analysis_dataset[[#This Row],[reference_year]] -> Angola-2018
A20: AGO | B20: Angola | C20: 2019 | D20: 7.086491e+10 | E20: 81193813808 | F20: 32375632 | G20: -1.0552341 | H20: 60.371307 | I20: 2188.83 | J20: 2507.87 | K20: 87.28 | L20: 54 | M20: 8.1329438e+10 | N20: -12.87 | O20: =vw_scenario_analysis_dataset[[#This Row],[reporter_name]] & "-" & vw_scenario_analysis_dataset[[#This Row],[reference_year]] -> Angola-2019
A21: AGO | B21: Angola | C21: 2020 | D21: 4.4008635e+10 | E21: 58512033806 | F21: 33451132 | G21: -5.2734913 | H21: 54.660403 | I21: 1315.61 | J21: 1749.18 | K21: 75.21 | L21: 60 | M21: 7.086491e+10 | N21: -37.9 | O21: =vw_scenario_analysis_dataset[[#This Row],[reporter_name]] & "-" & vw_scenario_analysis_dataset[[#This Row],[reference_year]] -> Angola-2020
A22: AGO | B22: Angola | C22: 2021 | D22: 6.8944324e+10 | E22: 78283923544 | F22: 34532429 | G22: 1.0905837 | H22: 62.528771 | I22: 1996.51 | J22: 2266.97 | K22: 88.07 | L22: 59 | M22: 4.4008635e+10 | N22: 56.66 | O22: =vw_scenario_analysis_dataset[[#This Row],[reporter_name]] & "-" & vw_scenario_analysis_dataset[[#This Row],[reference_year]] -> Angola-2021
A23: AGO | B23: Angola | C23: 2022 | D23: 1.025499e+11 | E23: 128000000000 | F23: 35635029 | G23: 3.5574921 | H23: 56.538072 | I23: 2877.78 | J23: 3591.97 | K23: 80.12 | L23: 52 | M23: 6.8944324e+10 | N23: 48.74 | O23: =vw_scenario_analysis_dataset[[#This Row],[reporter_name]] & "-" & vw_scenario_analysis_dataset[[#This Row],[reference_year]] -> Angola-2022
A24: AGO | B24: Angola | C24: 2023 | D24: 7.7463173e+10 | E24: 106000000000 | F24: 36749906 | G24: 1.3201659 | H24: 53.607013 | I24: 2107.85 | J24: 2884.36 | K24: 73.08 | L24: 55 | M24: 1.025499e+11 | N24: -24.46 | O24: =vw_scenario_analysis_dataset[[#This Row],[reporter_name]] & "-" & vw_scenario_analysis_dataset[[#This Row],[reference_year]] -> Angola-2023
A25: AGO | B25: Angola | C25: 2024 | D25: 7.8743269e+10 | E25: 103000000000 | F25: 37885849 | G25: 4.9526786 | H25: 49.848951 | I25: 2078.43 | J25: 2718.69 | K25: 76.45 | L25: 55 | M25: 7.7463173e+10 | N25: 1.65 | O25: =vw_scenario_analysis_dataset[[#This Row],[reporter_name]] & "-" & vw_scenario_analysis_dataset[[#This Row],[reference_year]] -> Angola-2024
A26: ALB | B26: Albania | C26: 2015 | D26: 3859314063 | E26: 11470171827 | F26: 2731293 | G26: 2.2277041 | H26: 71.279448 | I26: 1413 | J26: 4199.54 | K26: 33.65 | L26: 118 | O26: =vw_scenario_analysis_dataset[[#This Row],[reporter_name]] & "-" & vw_scenario_analysis_dataset[[#This Row],[reference_year]] -> Albania-2015
A27: ALB | B27: Albania | C27: 2016 | D27: 3924234833 | E27: 11988668785 | F27: 2689469 | G27: 3.9089355 | H27: 74.01445 | I27: 1459.11 | J27: 4457.63 | K27: 32.73 | L27: 122 | M27: 3859314063 | N27: 1.68 | O27: =vw_scenario_analysis_dataset[[#This Row],[reporter_name]] & "-" & vw_scenario_analysis_dataset[[#This Row],[reference_year]] -> Albania-2016
A28: ALB | B28: Albania | C28: 2017 | D28: 4.6026819e+09 | E28: 13258268436 | F28: 2648285 | G28: 3.2831759 | H28: 76.787382 | I28: 1737.99 | J28: 5006.36 | K28: 34.72 | L28: 120 | M28: 3924234833 | N28: 17.29 | O28: =vw_scenario_analysis_dataset[[#This Row],[reporter_name]] & "-" & vw_scenario_analysis_dataset[[#This Row],[reference_year]] -> Albania-2017
A29: ALB | B29: Albania | C29: 2018 | D29: 5.7517196e+09 | E29: 15379508330 | F29: 2607733 | G29: 3.6714193 | H29: 75.694078 | I29: 2205.64 | J29: 5897.65 | K29: 37.4 | L29: 115 | M29: 4.6026819e+09 | N29: 24.96 | O29: =vw_scenario_analysis_dataset[[#This Row],[reporter_name]] & "-" & vw_scenario_analysis_dataset[[#This Row],[reference_year]] -> Albania-2018
A30: ALB | B30: Albania | C30: 2019 | D30: 5.4388574e+09 | E30: 15585111614 | F30: 2567801 | G30: 2.0625779 | H30: 75.382129 | I30: 2118.1 | J30: 6069.44 | K30: 34.9 | L30: 115 | M30: 5.7517196e+09 | N30: -5.44 | O30: =vw_scenario_analysis_dataset[[#This Row],[reporter_name]] & "-" & vw_scenario_analysis_dataset[[#This Row],[reference_year]] -> Albania-2019
A31: ALB | B31: Albania | C31: 2020 | D31: 4.8312647e+09 | E31: 15241458745 | F31: 2528480 | G31: -3.3137564 | H31: 59.520699 | I31: 1910.74 | J31: 6027.91 | K31: 31.7 | L31: 116 | M31: 5.4388574e+09 | N31: -11.17 | O31: =vw_scenario_analysis_dataset[[#This Row],[reporter_name]] & "-" & vw_scenario_analysis_dataset[[#This Row],[reference_year]] -> Albania-2020
A32: ALB | B32: Albania | C32: 2021 | D32: 7.1245945e+09 | E32: 18031989573 | F32: 2489762 | G32: 8.9695762 | H32: 75.590404 | I32: 2861.56 | J32: 7242.46 | K32: 39.51 | L32: 113 | M32: 4.8312647e+09 | N32: 47.47 | O32: =vw_scenario_analysis_dataset[[#This Row],[reporter_name]] & "-" & vw_scenario_analysis_dataset[[#This Row],[reference_year]] -> Albania-2021
A33: ALB | B33: Albania | C33: 2022 | D33: 8.6124695e+09 | E33: 19017247014 | F33: 2451636 | G33: 4.8268006 | H33: 84.698044 | I33: 3512.95 | J33: 7756.96 | K33: 45.29 | L33: 109 | M33: 7.1245945e+09 | N33: 20.88 | O33: =vw_scenario_analysis_dataset[[#This Row],[reporter_name]] & "-" & vw_scenario_analysis_dataset[[#This Row],[reference_year]] -> Albania-2022
A34: ALB | B34: Albania | C34: 2023 | D34: 8.7497144e+09 | E34: 23491242727 | F34: 2411658 | G34: 4.0154172 | H34: 82.352493 | I34: 3628.09 | J34: 9740.7 | K34: 37.25 | L34: 110 | M34: 8.6124695e+09 | N34: 1.59 | O34: =vw_scenario_analysis_dataset[[#This Row],[reporter_name]] & "-" & vw_scenario_analysis_dataset[[#This Row],[reference_year]] -> Albania-2023
A35: ALB | B35: Albania | C35: 2024 | D35: 8.0023082e+09 | E35: 27037474263 | F35: 2377128 | G35: 4.0459285 | H35: 79.454636 | I35: 3366.38 | J35: 11374.01 | K35: 29.6 | L35: 100 | M35: 8.7497144e+09 | N35: -8.54 | O35: =vw_scenario_analysis_dataset[[#This Row],[reporter_name]] & "-" & vw_scenario_analysis_dataset[[#This Row],[reference_year]] -> Albania-2024
A36: AND | B36: Andorra | C36: 2015 | D36: 1.7900387e+08 | E36: 2789881259 | F36: 72174 | G36: 1.4341404 | I36: 2480.17 | J36: 38654.93 | K36: 6.42 | L36: 155 | O36: =vw_scenario_analysis_dataset[[#This Row],[reporter_name]] & "-" & vw_scenario_analysis_dataset[[#This Row],[reference_year]] -> Andorra-2015
A37: AND | B37: Andorra | C37: 2016 | D37: 1.9273462e+08 | E37: 2896610480 | F37: 72181 | G37: 3.7096781 | I37: 2670.16 | J37: 40129.82 | K37: 6.65 | L37: 156 | M37: 1.7900387e+08 | N37: 7.67 | O37: =vw_scenario_analysis_dataset[[#This Row],[reporter_name]] & "-" & vw_scenario_analysis_dataset[[#This Row],[reference_year]] -> Andorra-2016
A38: AND | B38: Andorra | C38: 2017 | D38: 2.3595981e+08 | E38: 3000162081 | F38: 73763 | G38: 0.34607189 | I38: 3198.89 | J38: 40672.99 | K38: 7.86 | L38: 156 | M38: 1.9273462e+08 | N38: 22.43 | O38: =vw_scenario_analysis_dataset[[#This Row],[reporter_name]] & "-" & vw_scenario_analysis_dataset[[#This Row],[reference_year]] -> Andorra-2017
A39: AND | B39: Andorra | C39: 2018 | D39: 2.5867073e+08 | E39: 3218419897 | F39: 75162 | G39: 1.5887655 | I39: 3441.51 | J39: 42819.77 | K39: 8.04 | L39: 152 | M39: 2.3595981e+08 | N39: 9.62 | O39: =vw_scenario_analysis_dataset[[#This Row],[reporter_name]] & "-" & vw_scenario_analysis_dataset[[#This Row],[reference_year]] -> Andorra-2018
A40: AND | B40: Andorra | C40: 2019 | D40: 2.5030315e+08 | E40: 3155149348 | F40: 76474 | G40: 2.0155476 | I40: 3273.05 | J40: 41257.8 | K40: 7.93 | L40: 150 | M40: 2.5867073e+08 | N40: -3.23 | O40: =vw_scenario_analysis_dataset[[#This Row],[reporter_name]] & "-" & vw_scenario_analysis_dataset[[#This Row],[reference_year]] -> Andorra-2019
...

Sheet Assumptions
A1: Global Trade & Supply Chain Intelligence Platform Bussiness Assumptions
A7: Scenario Information
A9: Scenario Name | C9: High Exports Growth
A10: Created by | C10: Mohammad Wasiq Khan
A11: Date | C11: =TODAY() -> 46234
A14: Country & Year Selection Dropdown
A16: Selected Country | C16: China | J16: LookUp Key | L16: =C16&"-"&C17 -> China-2017
A17: Selected Year | C17: 2017
A21: Business Assumptions
A23: Variable | C23: Current Value | E23: Unit | G23: Scenario Value | I23: Change %
A24: Total Exports | C24: =IFERROR(_xlfn.XLOOKUP($L$16,SQL_Data_Import!$O:$O,SQL_Data_Import!$D:$D)/1000000000, "No Data Available") -> 4526.741 | E24: Billion USD | G24: 5000 | I24: =IFERROR((G24-C24)/C24,"") -> 0.1045474
A25: GDP | C25: =IFERROR(_xlfn.XLOOKUP($L$16,SQL_Data_Import!$O:$O,SQL_Data_Import!$E:$E)/1000000000, "No Data Available") -> 12500 | E25: Billion USD | G25: 13298.98 | I25: =IFERROR((G25-C25)/C25,"") -> 0.0639184
A26: Population | C26: =IFERROR(_xlfn.XLOOKUP($L$16,SQL_Data_Import!$O:$O,SQL_Data_Import!$F:$F)/1000000000, "No Data Available") -> 1.396215 | E26: Billion People | G26: 1.54 | I26: =IFERROR((G26-C26)/C26,"") -> 0.10298199
A27: GDP Growth % | C27: =IFERROR(_xlfn.XLOOKUP($L$16,SQL_Data_Import!$O:$O,SQL_Data_Import!$G:$G), "No Data Available") -> 6.8912392 | E27: % | G27: 1.62 | I27: =IFERROR((G27-C27)/C27,"") -> -0.76491891
A28: Trade % Of GDP | C28: =IFERROR(_xlfn.XLOOKUP($L$16,SQL_Data_Import!$O:$O,SQL_Data_Import!$H:$H), "No Data Available") -> 36.950853 | E28: % | G28: 63.2 | I28: =IFERROR((G28-C28)/C28,"") -> 0.71038002
A29: Export per Capita | C29: =IFERROR(_xlfn.XLOOKUP($L$16,SQL_Data_Import!$O:$O,SQL_Data_Import!$I:$I),"No Data Available") -> 3242.15 | E29: USD | G29: 630.75 | I29: =IFERROR((G29-C29)/C29,"") -> -0.80545317
A30: GDP per Capita | C30: =IFERROR(_xlfn.XLOOKUP($L$16,SQL_Data_Import!$O:$O,SQL_Data_Import!$J:$J), "No Data Available") -> 8952.78 | E30: USD | G30: 2787.98 | I30: =IFERROR((G30-C30)/C30,"") -> -0.68859058
A31: Export to GDP Ratio % | C31: =IFERROR(_xlfn.XLOOKUP($L$16,SQL_Data_Import!$O:$O,SQL_Data_Import!$K:$K), "No Data Available") -> 36.21 | E31: % | G31: 31.5 | I31: =IFERROR((G31-C31)/C31,"") -> -0.13007457
A35: Instructions
A37: 1. Select a country.
A39: 2. Select a year.
A41: 3. Enter Scenario Values only.
A43: 4. Do not edit Current Values.
A45: 5. Dashboard updates automatically.
A47: 6. Scenario calculations are performed in the Scenario_Model sheet.

Sheet Scenario_Model
A1: Global Trade & Supply Chain Intelligence Platform Scenario Analysis Model
A7: Scenario Information Section
A9: Scenario Name | D9: =Assumptions!$C$9 -> High Exports Growth
A10: Country | D10: =Assumptions!C16 -> China
A11: Year | D11: =Assumptions!C17 -> 2017
A12: Created Date | D12: =TODAY() -> 46234
A15: Current VS Scenario Comparison
A17: KPI | C17: Current | E17: Scenario | G17: Difference | I17: Change% | K17: Unit
A18: Total Exports | C18: =Assumptions!C24 -> 4526.741 | E18: =Assumptions!G24 -> 5000 | G18: =E18-C18 -> 473.25899 | I18: =Assumptions!I24 -> 0.1045474 | K18: Billion USD
A19: GDP | C19: =Assumptions!C25 -> 12500 | E19: =Assumptions!G25 -> 13298.98 | G19: =E19-C19 -> 798.98 | I19: =Assumptions!I25 -> 0.0639184 | K19: Billion USD
A20: Population | C20: =Assumptions!C26 -> 1.396215 | E20: =Assumptions!G26 -> 1.54 | G20: =E20-C20 -> 0.143785 | I20: =Assumptions!I26 -> 0.10298199 | K20: Billion People
A21: GDP Growth% | C21: =Assumptions!C27 -> 6.8912392 | E21: =Assumptions!G27 -> 1.62 | G21: =E21-C21 -> -5.2712392 | I21: =Assumptions!I27 -> -0.76491891 | K21: %
A22: Trade% of GDP | C22: =Assumptions!C28 -> 36.950853 | E22: =Assumptions!G28 -> 63.2 | G22: =E22-C22 -> 26.249147 | I22: =Assumptions!I28 -> 0.71038002 | K22: %
A23: Exports per Capita | C23: =Assumptions!C29 -> 3242.15 | E23: =Assumptions!G29 -> 630.75 | G23: =E23-C23 -> -2611.4 | I23: =Assumptions!I29 -> -0.80545317 | K23: USD
A24: GDP per Capita | C24: =Assumptions!C30 -> 8952.78 | E24: =Assumptions!G30 -> 2787.98 | G24: =E24-C24 -> -6164.8 | I24: =Assumptions!I30 -> -0.68859058 | K24: USD
A25: Exports/GDP Ratio% | C25: =Assumptions!C31 -> 36.21 | E25: =Assumptions!G31 -> 31.5 | G25: =E25-C25 -> -4.71 | I25: =Assumptions!I31 -> -0.13007457 | K25: %
A28: Projected Business KPI's
A31: KPI | C31: Projected Values
A32: Projected Exports per Capita | C32: =E18/E20 -> 3246.7532
A33: Projected GDP per Capita | C33: =E19/E20 -> 8635.7013
A34: Projected Export/GDP Ratio | C34: =E18/E19 -> 0.37596868
A38: Performance Indicators
A40: KPI | C40: Status
A41: Total Exports | C41: =IF(I18>0,"Improved",IF(I18<0,"Declined","No Change")) -> Improved
A42: GDP | C42: =IF(I19>0,"Improved",IF(I19<0,"Declined","No Change")) -> Improved
A43: Population | C43: =IF(I20>0,"Improved",IF(I20<0,"Declined","No Change")) -> Improved
A44: GDP Growth% | C44: =IF(I21>0,"Improved",IF(I21<0,"Declined","No Change")) -> Declined
A45: Trade% of GDP | C45: =IF(I22>0,"Improved",IF(I22<0,"Declined","No Change")) -> Improved
A46: Exports per Capita | C46: =IF(I23>0,"Improved",IF(I23<0,"Declined","No Change")) -> Declined
A47: GDP per Capita | C47: =IF(I24>0,"Improved",IF(I24<0,"Declined","No Change")) -> Declined
A48: Exports/GDP Ratio% | C48: =IF(I25>0,"Improved",IF(I25<0,"Declined","No Change")) -> Declined
A51: Key Insights
A53: =IF(I18>0.2, "Exports increased significantly.", "Exports increased moderately.") -> Exports increased moderately.
A55: =IF(C34>0.3, "Trade intensity improved.", "Trade intensity remained stable.") -> Trade intensity improved.
A57: =IF(C33>C24, "Income per capita improved.", "No improvement observed.") -> No improvement observed.

Sheet Sensitivity_Analysis
A1: Global Trade & Supply Chain Intelligence Platform Sensitivity Analysis Model
A7: Scenario Information Section
A9: Scenario Name | D9: =Assumptions!C9 -> High Exports Growth
A10: Country | D10: =Assumptions!C16 -> China
A11: Year | D11: =Assumptions!C17 -> 2017
A12: Created Date | D12: =TODAY() -> 46234
A14: Current Exports | D14: =Scenario_Model!$C$18 -> 4526.741 | G14: Billion USD
A15: Current GDP | D15: =Scenario_Model!$C$19 -> 12500 | G15: Billion USD
A16: Current Population | D16: =Scenario_Model!$C$20 -> 1.396215 | G16: Billion People
A18: Exports Sensitivity Analysis
A21: Export Change % | C21: Projected Exports | E21: Exports per Capita | G21: Export/GDP Ratio
A22: -0.1 | C22: =Assumptions!$C$24*(1+Sensitivity_Analysis!A22) -> 4074.0669 | E22: =C22/Scenario_Model!$C$20 -> 2917.9366 | G22: =C22/Scenario_Model!$C$19 -> 0.32592535
A23: -0.05 | C23: =Assumptions!$C$24*(1+Sensitivity_Analysis!A23) -> 4300.404 | E23: =C23/Scenario_Model!$C$20 -> 3080.0442 | G23: =C23/Scenario_Model!$C$19 -> 0.34403232
A24: 0 | C24: =Assumptions!$C$24*(1+Sensitivity_Analysis!A24) -> 4526.741 | E24: =C24/Scenario_Model!$C$20 -> 3242.1518 | G24: =C24/Scenario_Model!$C$19 -> 0.36213928
A25: 0.05 | C25: =Assumptions!$C$24*(1+Sensitivity_Analysis!A25) -> 4753.0781 | E25: =C25/Scenario_Model!$C$20 -> 3404.2594 | G25: =C25/Scenario_Model!$C$19 -> 0.38024624
A26: 0.1 | C26: =Assumptions!$C$24*(1+Sensitivity_Analysis!A26) -> 4979.4151 | E26: =C26/Scenario_Model!$C$20 -> 3566.367 | G26: =C26/Scenario_Model!$C$19 -> 0.39835321
A30: GDP Sensitivity Analysis
A33: GDP Change % | C33: GDP | E33: GDP per Capita | G33: Export/GDP Ratio
A34: -0.1 | C34: =Assumptions!$C$25*(1+Sensitivity_Analysis!A34) -> 11250 | E34: =C34/Assumptions!$C$26 -> 8057.4983 | G34: =Assumptions!$C$24/Sensitivity_Analysis!C34 -> 0.40237698
A35: -0.05 | C35: =Assumptions!$C$25*(1+Sensitivity_Analysis!A35) -> 11875 | E35: =C35/Assumptions!$C$26 -> 8505.1371 | G35: =Assumptions!$C$24/Sensitivity_Analysis!C35 -> 0.38119924
A36: 0 | C36: =Assumptions!$C$25*(1+Sensitivity_Analysis!A36) -> 12500 | E36: =C36/Assumptions!$C$26 -> 8952.7759 | G36: =Assumptions!$C$24/Sensitivity_Analysis!C36 -> 0.36213928
A37: 0.05 | C37: =Assumptions!$C$25*(1+Sensitivity_Analysis!A37) -> 13125 | E37: =C37/Assumptions!$C$26 -> 9400.4147 | G37: =Assumptions!$C$24/Sensitivity_Analysis!C37 -> 0.34489455
A38: 0.1 | C38: =Assumptions!$C$25*(1+Sensitivity_Analysis!A38) -> 13750 | E38: =C38/Assumptions!$C$26 -> 9848.0535 | G38: =Assumptions!$C$24/Sensitivity_Analysis!C38 -> 0.32921753
A42: Population Sensitivity Analysis
A44: Population Change % | C44: Exports per Capita | E44: Population in Billions | G44: GDP per Capita
A45: -0.1 | C45: =Assumptions!$C$24/Sensitivity_Analysis!E45 -> 3602.3909 | E45: =Assumptions!$C$26*(1+Sensitivity_Analysis!$A45) -> 1.2565935 | G45: =Assumptions!$C$25/Sensitivity_Analysis!E45 -> 9947.5288
A46: -0.05 | C46: =Assumptions!$C$24/Sensitivity_Analysis!E46 -> 3412.7914 | E46: =Assumptions!$C$26*(1+Sensitivity_Analysis!$A46) -> 1.3264042 | G46: =Assumptions!$C$25/Sensitivity_Analysis!E46 -> 9423.9746
A47: 0 | C47: =Assumptions!$C$24/Sensitivity_Analysis!E47 -> 3242.1518 | E47: =Assumptions!$C$26*(1+Sensitivity_Analysis!$A47) -> 1.396215 | G47: =Assumptions!$C$25/Sensitivity_Analysis!E47 -> 8952.7759
A48: 0.05 | C48: =Assumptions!$C$24/Sensitivity_Analysis!E48 -> 3087.7636 | E48: =Assumptions!$C$26*(1+Sensitivity_Analysis!$A48) -> 1.4660258 | G48: =Assumptions!$C$25/Sensitivity_Analysis!E48 -> 8526.4532
A49: 0.1 | C49: =Assumptions!$C$24/Sensitivity_Analysis!E49 -> 2947.4107 | E49: =Assumptions!$C$26*(1+Sensitivity_Analysis!$A49) -> 1.5358365 | G49: =Assumptions!$C$25/Sensitivity_Analysis!E49 -> 8138.8872
A53: Country Performance Summary
A55: KPI | C55: Current | E55: Best Scenario | G55: Worst Scenario | H55: MaximumChange | I55: Business Impact | J55: Business Impact
A56: Exports | C56: =Scenario_Model!C18 -> 4526.741 | E56: =MAX(C22:D26) -> 4979.4151 | G56: =MIN(C22:D26) -> 4074.0669 | H56: =E56-G56 -> 905.3482 | J56: =IF(H56>=1000, "Very High Impact", IF(H56>=500, "Medium Impact", IF(H56>=100, "Moderate Impact", "Low Impact"))) -> Medium Impact
A57: GDP | C57: =Scenario_Model!C19 -> 12500 | E57: =MAX(C34:D38) -> 13750 | G57: =MIN(C34:D38) -> 11250 | H57: =E57-G57 -> 2500 | J57: =IF(H57>=1000, "Very High Impact", IF(H57>=500, "Medium Impact", IF(H57>=100, "Moderate Impact", "Low Impact"))) -> Very High Impact
A58: Exports per Capita | C58: =Scenario_Model!C23 -> 3242.15 | E58: =MAX(C45:D49) -> 3602.3909 | G58: =MIN(C45:D49) -> 2947.4107 | H58: =E58-G58 -> 654.98017 | J58: =IF(H58>=1000, "Very High Impact", IF(H58>=500, "Medium Impact", IF(H58>=100, "Moderate Impact", "Low Impact"))) -> Medium Impact
A59: GDP per Capita | C59: =Scenario_Model!C24 -> 8952.78 | E59: =MAX(G45:H49) -> 9947.5288 | G59: =MIN(G45:H49) -> 8138.8872 | H59: =E59-G59 -> 1808.6416 | J59: =IF(H59>=1000, "Very High Impact", IF(H59>=500, "Medium Impact", IF(H59>=100, "Moderate Impact", "Low Impact"))) -> Very High Impact
A60: Export/GDP Ratio | C60: =Scenario_Model!C25 -> 36.21 | E60: =MAX(G34:H38) -> 0.40237698 | G60: =MIN(G34:H38) -> 0.32921753 | H60: =E60-G60 -> 0.073159451 | J60: =IF(H60>=1000, "Very High Impact", IF(H60>=500, "Medium Impact", IF(H60>=100, "Moderate Impact", "Low Impact"))) -> Low Impact

Sheet Dashboard

Sheet Hidden Sheet
A1: Select Country | E1: Select Year
A2: Aruba | E2: 2015
A3: Afghanistan | E3: 2016
A4: Angola | E4: 2017
A5: Albania | E5: 2018
A6: Andorra | E6: 2019
A7: United Arab Emirates | E7: 2020
A8: Argentina | E8: 2021
A9: Armenia | E9: 2022
A10: Antigua and Barbuda | E10: 2023
A11: Australia | E11: 2024
A12: Austria
A13: Azerbaijan
A14: Burundi
A15: Belgium
A16: Benin
A17: Burkina Faso
A18: Bangladesh
A19: Bulgaria
A20: Bahrain
A21: Bahamas
A22: Bosnia Herzegovina
A23: Belarus
... A183: Zimbabwe
